Workbook

Sheet Parâmetros
A1: PARÂMETROS DE MARKUP
A2: Marv Martins Notari Construtora Ltda — Obra 40200 Empreita Recanto Cataratas Thermas Resort
A4: FAIXA DE MARKUP SOLICITADA
A5: Markup mínimo (piso da faixa) | B5: 0.35 | C5: Piso da faixa de 35% a 40% solicitada. Alimenta as colunas '+35%' de todas as abas.
A6: Markup máximo (teto da faixa) | B6: 0.4 | C6: Teto da faixa de 35% a 40% solicitada. Alimenta as colunas '+40%' de todas as abas.
A7: MARKUP APLICADO | B7: 0.375 | C7: CÉLULA EDITÁVEL. Altere aqui e TODAS as abas recalculam automaticamente. Padrão = 37,5% (ponto médio da faixa de 35% a 40%). Digite 0,35 para 35% ou 0,40 para 40%.
A9: COMO O MARKUP É APLICADO
A10: • O markup incide sobre o VALOR UNITÁRIO de mão de obra de cada item.
A11: • O total do item é recalculado como: quantidade contratada x valor unitário majorado.
A12: • A quantidade contratada NÃO é alterada — apenas o preço.
A13: • Como a quantidade é constante, o total majorado equivale ao total original x (1 + markup).
A14: • Todos os 6 contratos são de mão de obra: o valor de material é 0,00 em 100% dos itens, por isso a coluna de material foi omitida.
A15: • Itens iniciais e itens de aditivo recebem o mesmo markup.
A17: LEGENDA DE CORES
A18: Texto azul | C18: Valor digitado, extraído do contrato em PDF (quantidade e valor unitário).
A19: Texto preto | C19: Fórmula calculada na própria aba.
A20: Texto verde | C20: Link para a aba 'Itens Consolidados', que é a fonte única dos dados.
A21: Fundo amarelo | C21: Célula editável pelo usuário e linhas de total.
A22: Fundo creme | C22: Item proveniente de aditivo, não do contrato inicial.
A25: ORIGEM DOS DADOS
A26: Todos os valores foram extraídos dos contratos em PDF emitidos por JESSICA RIBEIRO em 21/08/2026, revisão R00. Os arquivos de origem estão indicados no cabeçalho de cada aba de contrato e na aba 'Conferência'.

Sheet Resumo
A1: RESUMO DOS CONTRATOS COM MARKUP
A2: Todos os valores calculados a partir da aba 'Itens Consolidados'. O percentual aplicado é o da célula Parâmetros!B7.
A3: Markup aplicado: | C3: =Parâmetros!$B$7 -> 0.375 | D3: ← altere em Parâmetros!B7 para recalcular a planilha inteira
A5: Contrato | B5: Fornecedor | C5: CNPJ | D5: Objeto do contrato | E5: Início | F5: Término | G5: Nº itens | H5: Valor inicial | I5: Valor aditivos | J5: Valor total original | K5: Total +35% | L5: Total +40% | M5: Total aplicado | N5: Acréscimo (R$)
A6: CT/149 | B6: 53.000.661 WAGNER LUIZ BACKES MACHADO | C6: 53.000.661/0001-83 | D6: Fornecimento de mão de obra estrutura metálica doca maestra. | E6: 12/12/2025 | F6: 12/03/2026 | G6: =COUNTIFS('Itens Consolidados'!$A$5:$A$40,$A6) -> 13 | H6: =SUMIFS('Itens Consolidados'!$L$5:$L$40,'Itens Consolidados'!$A$5:$A$40,$A6,'Itens Consolidados'!$D$5:$D$40,"Inicial") -> 42000 | I6: =J6-H6 -> 168260 | J6: =SUMIFS('Itens Consolidados'!$L$5:$L$40,'Itens Consolidados'!$A$5:$A$40,$A6) -> 210260 | K6: =SUMIFS('Itens Consolidados'!$N$5:$N$40,'Itens Consolidados'!$A$5:$A$40,$A6) -> 283851 | L6: =SUMIFS('Itens Consolidados'!$P$5:$P$40,'Itens Consolidados'!$A$5:$A$40,$A6) -> 294364 | M6: =SUMIFS('Itens Consolidados'!$R$5:$R$40,'Itens Consolidados'!$A$5:$A$40,$A6) -> 289107.5 | N6: =M6-J6 -> 78847.5
A7: CT/164 | B7: CAM EMPREITEIRA DE MAO DE OBRA LTDA | C7: 01.128.174/0001-05 | D7: Realizar o polimento mecanizado de piso e lajes de concreto. | E7: 03/01/2026 | F7: 30/06/2026 | G7: =COUNTIFS('Itens Consolidados'!$A$5:$A$40,$A7) -> 6 | H7: =SUMIFS('Itens Consolidados'!$L$5:$L$40,'Itens Consolidados'!$A$5:$A$40,$A7,'Itens Consolidados'!$D$5:$D$40,"Inicial") -> 241857.6 | I7: =J7-H7 -> 54816.21 | J7: =SUMIFS('Itens Consolidados'!$L$5:$L$40,'Itens Consolidados'!$A$5:$A$40,$A7) -> 296673.81 | K7: =SUMIFS('Itens Consolidados'!$N$5:$N$40,'Itens Consolidados'!$A$5:$A$40,$A7) -> 400509.64 | L7: =SUMIFS('Itens Consolidados'!$P$5:$P$40,'Itens Consolidados'!$A$5:$A$40,$A7) -> 415343.33 | M7: =SUMIFS('Itens Consolidados'!$R$5:$R$40,'Itens Consolidados'!$A$5:$A$40,$A7) -> 407926.49 | N7: =M7-J7 -> 111252.68
A8: CT/196 | B8: ROSENILDE RODRIGUES LINDOLFO DE SOUZA | C8: 42.578.638/0001-54 | D8: Fornecimento de mão de obra especializada para montagem e execução de paredes em drywall, conforme especificações do projeto. | E8: 18/05/2026 | F8: 20/06/2026 | G8: =COUNTIFS('Itens Consolidados'!$A$5:$A$40,$A8) -> 6 | H8: =SUMIFS('Itens Consolidados'!$L$5:$L$40,'Itens Consolidados'!$A$5:$A$40,$A8,'Itens Consolidados'!$D$5:$D$40,"Inicial") -> 32500 | I8: =J8-H8 -> 92043.05 | J8: =SUMIFS('Itens Consolidados'!$L$5:$L$40,'Itens Consolidados'!$A$5:$A$40,$A8) -> 124543.05 | K8: =SUMIFS('Itens Consolidados'!$N$5:$N$40,'Itens Consolidados'!$A$5:$A$40,$A8) -> 168133.12 | L8: =SUMIFS('Itens Consolidados'!$P$5:$P$40,'Itens Consolidados'!$A$5:$A$40,$A8) -> 174360.27 | M8: =SUMIFS('Itens Consolidados'!$R$5:$R$40,'Itens Consolidados'!$A$5:$A$40,$A8) -> 171246.69 | N8: =M8-J8 -> 46703.644
A9: CT/212 | B9: AGR DELAVI PISOS LTDA | C9: 48.094.845/0001-10 | D9: Fornecimento de mão de obra para execução de piso Fulget no Centro de Eventos do Hotel Recanto e do Restaurante. | E9: 08/07/2026 | F9: 08/08/2026 | G9: =COUNTIFS('Itens Consolidados'!$A$5:$A$40,$A9) -> 1 | H9: =SUMIFS('Itens Consolidados'!$L$5:$L$40,'Itens Consolidados'!$A$5:$A$40,$A9,'Itens Consolidados'!$D$5:$D$40,"Inicial") -> 95923.2 | I9: =J9-H9 -> 0 | J9: =SUMIFS('Itens Consolidados'!$L$5:$L$40,'Itens Consolidados'!$A$5:$A$40,$A9) -> 95923.2 | K9: =SUMIFS('Itens Consolidados'!$N$5:$N$40,'Itens Consolidados'!$A$5:$A$40,$A9) -> 129496.32 | L9: =SUMIFS('Itens Consolidados'!$P$5:$P$40,'Itens Consolidados'!$A$5:$A$40,$A9) -> 134292.48 | M9: =SUMIFS('Itens Consolidados'!$R$5:$R$40,'Itens Consolidados'!$A$5:$A$40,$A9) -> 131894.4 | N9: =M9-J9 -> 35971.2
A10: CT/216 | B10: LOURIVAL BONFIM 66371490982 | C10: 13.932.826/0001-30 | D10: Fornecimento de mão de obra para execução do revestimento em ACM na região do porte-cochère do Centro de Eventos do Hotel Recanto. | E10: 25/06/2026 | F10: 31/07/2026 | G10: =COUNTIFS('Itens Consolidados'!$A$5:$A$40,$A10) -> 2 | H10: =SUMIFS('Itens Consolidados'!$L$5:$L$40,'Itens Consolidados'!$A$5:$A$40,$A10,'Itens Consolidados'!$D$5:$D$40,"Inicial") -> 60000 | I10: =J10-H10 -> 37671 | J10: =SUMIFS('Itens Consolidados'!$L$5:$L$40,'Itens Consolidados'!$A$5:$A$40,$A10) -> 97671 | K10: =SUMIFS('Itens Consolidados'!$N$5:$N$40,'Itens Consolidados'!$A$5:$A$40,$A10) -> 131855.85 | L10: =SUMIFS('Itens Consolidados'!$P$5:$P$40,'Itens Consolidados'!$A$5:$A$40,$A10) -> 136739.4 | M10: =SUMIFS('Itens Consolidados'!$R$5:$R$40,'Itens Consolidados'!$A$5:$A$40,$A10) -> 134297.62 | N10: =M10-J10 -> 36626.625
A11: CT/217 | B11: 60.623.714 VALDEMIR MENDES DA SILVA | C11: 60.623.714/0001-88 | D11: Fornecimento de mão de obra para execução de parede em drywall e execução de sanca do Foyer. | E11: 20/07/2026 | F11: 20/08/2026 | G11: =COUNTIFS('Itens Consolidados'!$A$5:$A$40,$A11) -> 8 | H11: =SUMIFS('Itens Consolidados'!$L$5:$L$40,'Itens Consolidados'!$A$5:$A$40,$A11,'Itens Consolidados'!$D$5:$D$40,"Inicial") -> 23605.65 | I11: =J11-H11 -> 1915 | J11: =SUMIFS('Itens Consolidados'!$L$5:$L$40,'Itens Consolidados'!$A$5:$A$40,$A11) -> 25520.65 | K11: =SUMIFS('Itens Consolidados'!$N$5:$N$40,'Itens Consolidados'!$A$5:$A$40,$A11) -> 34452.878 | L11: =SUMIFS('Itens Consolidados'!$P$5:$P$40,'Itens Consolidados'!$A$5:$A$40,$A11) -> 35728.91 | M11: =SUMIFS('Itens Consolidados'!$R$5:$R$40,'Itens Consolidados'!$A$5:$A$40,$A11) -> 35090.894 | N11: =M11-J11 -> 9570.2437
A12: TOTAL GERAL | G12: =SUM(G6:G11) -> 36 | H12: =SUM(H6:H11) -> 495886.45 | I12: =SUM(I6:I11) -> 354705.26 | J12: =SUM(J6:J11) -> 850591.71 | K12: =SUM(K6:K11) -> 1148298.8 | L12: =SUM(L6:L11) -> 1190828.4 | M12: =SUM(M6:M11) -> 1169563.6 | N12: =SUM(N6:N11) -> 318971.89
A15: COMPARATIVO DE CENÁRIOS
A16: Cenário | C16: Markup | D16: Total dos 6 contratos | E16: Acréscimo sobre o original
A17: Valor original (sem markup) | C17: 0 | D17: =J12 -> 850591.71 | E17: =D17-$J$12 -> 0
A18: Piso da faixa | C18: =Parâmetros!$B$5 -> 0.35 | D18: =K12 -> 1148298.8 | E18: =D18-$J$12 -> 297707.1
A19: Teto da faixa | C19: =Parâmetros!$B$6 -> 0.4 | D19: =L12 -> 1190828.4 | E19: =D19-$J$12 -> 340236.68
A20: APLICADO NA PLANILHA | C20: =Parâmetros!$B$7 -> 0.375 | D20: =M12 -> 1169563.6 | E20: =D20-$J$12 -> 318971.89

Sheet Itens Consolidados
A1: ITENS CONSOLIDADOS — TODOS OS CONTRATOS
A2: Tabela mestre. Quantidade e valor unitário original (azul) são os únicos valores digitados; todo o resto é fórmula. Para incluir novos contratos, acrescente linhas ao final desta aba.
A4: Contrato | B4: Fornecedor | C4: Unid. construtiva | D4: Origem | E4: Data do aditivo | F4: Referência | G4: Código | H4: Descrição | I4: Un. | J4: Quantidade | K4: Vl. unit. original | L4: Total original | M4: Vl. unit. +35% | N4: Total +35% | O4: Vl. unit. +40% | P4: Total +40% | Q4: Vl. unit. aplicado | R4: Total aplicado | S4: Acréscimo (R$)
A5: CT/149 | B5: 53.000.661 WAGNER LUIZ BACKES MACHADO | C5: 5 - Foyer e restaurante | D5: Inicial | F5: 00.001.001.001 | G5: 80285 | H5: Estrutura metálica, escoramento e telhado doca | I5: vb | J5: 1 | K5: 42000 | L5: =J5*K5 -> 42000 | M5: =K5*(1+Parâmetros!$B$5) -> 56700 | N5: =J5*M5 -> 56700 | O5: =K5*(1+Parâmetros!$B$6) -> 58800 | P5: =J5*O5 -> 58800 | Q5: =K5*(1+Parâmetros!$B$7) -> 57750 | R5: =J5*Q5 -> 57750 | S5: =R5-L5 -> 15750
A6: CT/149 | B6: 53.000.661 WAGNER LUIZ BACKES MACHADO | C6: 5 - Foyer e restaurante | D6: Aditivo 1 | E6: 31/03/2026 | F6: 00.001.001.002 | G6: 80285 | H6: Execução de cobertura lateral de 344,35 m², incluindo montagem da estrutura metálica, instalação de telhas com rufos e calhas. Aplicação de fundo anti ferrugem em todas as peças. | I6: vb | J6: 1 | K6: 51300 | L6: =J6*K6 -> 51300 | M6: =K6*(1+Parâmetros!$B$5) -> 69255 | N6: =J6*M6 -> 69255 | O6: =K6*(1+Parâmetros!$B$6) -> 71820 | P6: =J6*O6 -> 71820 | Q6: =K6*(1+Parâmetros!$B$7) -> 70537.5 | R6: =J6*Q6 -> 70537.5 | S6: =R6-L6 -> 19237.5
A7: CT/149 | B7: 53.000.661 WAGNER LUIZ BACKES MACHADO | C7: 5 - Foyer e restaurante | D7: Aditivo 1 | E7: 31/03/2026 | F7: 00.001.001.003 | G7: 80285 | H7: Execução de cobertura lateral de 212 m², parte métrica montada com rufos e calhas, incluindo remoção de 02 bicos metálicos. Aplicação de fundo anti ferrugem em todas as peças. | I7: vb | J7: 1 | K7: 26600 | L7: =J7*K7 -> 26600 | M7: =K7*(1+Parâmetros!$B$5) -> 35910 | N7: =J7*M7 -> 35910 | O7: =K7*(1+Parâmetros!$B$6) -> 37240 | P7: =J7*O7 -> 37240 | Q7: =K7*(1+Parâmetros!$B$7) -> 36575 | R7: =J7*Q7 -> 36575 | S7: =R7-L7 -> 9975
A8: CT/149 | B8: 53.000.661 WAGNER LUIZ BACKES MACHADO | C8: 5 - Foyer e restaurante | D8: Aditivo 1 | E8: 31/03/2026 | F8: 00.001.001.004 | G8: 80285 | H8: Remoção de estrutura metálica com fachada em ACM, remoção completa de letreiro, ACM e estrutura metálica. | I8: vb | J8: 1 | K8: 10500 | L8: =J8*K8 -> 10500 | M8: =K8*(1+Parâmetros!$B$5) -> 14175 | N8: =J8*M8 -> 14175 | O8: =K8*(1+Parâmetros!$B$6) -> 14700 | P8: =J8*O8 -> 14700 | Q8: =K8*(1+Parâmetros!$B$7) -> 14437.5 | R8: =J8*Q8 -> 14437.5 | S8: =R8-L8 -> 3937.5
A9: CT/149 | B9: 53.000.661 WAGNER LUIZ BACKES MACHADO | C9: 5 - Foyer e restaurante | D9: Aditivo 2 | E9: 03/07/2026 | F9: 00.001.001.005 | G9: 80285 | H9: Execução de cobertura metálica para telhado tipo shingle, incluindo adequação e tratamento anticorrosivo da estrutura, fechamento com telha de zinco, instalação de rufos, desmontagem de estrutura metálica e fabricação de suporte metálico. | I9: vb | J9: 1 | K9: 40000 | L9: =J9*K9 -> 40000 | M9: =K9*(1+Parâmetros!$B$5) -> 54000 | N9: =J9*M9 -> 54000 | O9: =K9*(1+Parâmetros!$B$6) -> 56000 | P9: =J9*O9 -> 56000 | Q9: =K9*(1+Parâmetros!$B$7) -> 55000 | R9: =J9*Q9 -> 55000 | S9: =R9-L9 -> 15000
A10: CT/149 | B10: 53.000.661 WAGNER LUIZ BACKES MACHADO | C10: 5 - Foyer e restaurante | D10: Aditivo 2 | E10: 03/07/2026 | F10: 00.001.001.006 | G10: 80285 | H10: Ajuste na calha do Hermes; foi feita uma nova dobragem na calha. | I10: vb | J10: 1 | K10: 1200 | L10: =J10*K10 -> 1200 | M10: =K10*(1+Parâmetros!$B$5) -> 1620 | N10: =J10*M10 -> 1620 | O10: =K10*(1+Parâmetros!$B$6) -> 1680 | P10: =J10*O10 -> 1680 | Q10: =K10*(1+Parâmetros!$B$7) -> 1650 | R10: =J10*Q10 -> 1650 | S10: =R10-L10 -> 450
A11: CT/149 | B11: 53.000.661 WAGNER LUIZ BACKES MACHADO | C11: 5 - Foyer e restaurante | D11: Aditivo 2 | E11: 03/07/2026 | F11: 00.001.001.007 | G11: 80285 | H11: Execução do fechamento lateral centro de eventos. | I11: vb | J11: 1 | K11: 14340 | L11: =J11*K11 -> 14340 | M11: =K11*(1+Parâmetros!$B$5) -> 19359 | N11: =J11*M11 -> 19359 | O11: =K11*(1+Parâmetros!$B$6) -> 20076 | P11: =J11*O11 -> 20076 | Q11: =K11*(1+Parâmetros!$B$7) -> 19717.5 | R11: =J11*Q11 -> 19717.5 | S11: =R11-L11 -> 5377.5
A12: CT/149 | B12: 53.000.661 WAGNER LUIZ BACKES MACHADO | C12: 5 - Foyer e restaurante | D12: Aditivo 2 | E12: 03/07/2026 | F12: 00.001.001.008 | G12: 80285 | H12: Preparação das terças para receber uma nova calha, execução de rufo entre o Vivace e Maestra. | I12: vb | J12: 1 | K12: 4900 | L12: =J12*K12 -> 4900 | M12: =K12*(1+Parâmetros!$B$5) -> 6615 | N12: =J12*M12 -> 6615 | O12: =K12*(1+Parâmetros!$B$6) -> 6860 | P12: =J12*O12 -> 6860 | Q12: =K12*(1+Parâmetros!$B$7) -> 6737.5 | R12: =J12*Q12 -> 6737.5 | S12: =R12-L12 -> 1837.5
A13: CT/149 | B13: 53.000.661 WAGNER LUIZ BACKES MACHADO | C13: 5 - Foyer e restaurante | D13: Aditivo 3 | E13: 28/07/2026 | F13: 00.001.001.009 | G13: 80285 | H13: Fabricação e instalação de 60 m de calha — Maestra. | I13: vb | J13: 1 | K13: 7200 | L13: =J13*K13 -> 7200 | M13: =K13*(1+Parâmetros!$B$5) -> 9720 | N13: =J13*M13 -> 9720 | O13: =K13*(1+Parâmetros!$B$6) -> 10080 | P13: =J13*O13 -> 10080 | Q13: =K13*(1+Parâmetros!$B$7) -> 9900 | R13: =J13*Q13 -> 9900 | S13: =R13-L13 -> 2700
A14: CT/149 | B14: 53.000.661 WAGNER LUIZ BACKES MACHADO | C14: 5 - Foyer e restaurante | D14: Aditivo 3 | E14: 28/07/2026 | F14: 00.001.001.010 | G14: 80285 | H14: Fabricação e instalação de 58,00 metros lineares de rufo, incluindo vedação dupla entre a laje destinada aos aparelhos de ar-condicionado e a cobertura em telhas shingle. | I14: vb | J14: 1 | K14: 2320 | L14: =J14*K14 -> 2320 | M14: =K14*(1+Parâmetros!$B$5) -> 3132 | N14: =J14*M14 -> 3132 | O14: =K14*(1+Parâmetros!$B$6) -> 3248 | P14: =J14*O14 -> 3248 | Q14: =K14*(1+Parâmetros!$B$7) -> 3190 | R14: =J14*Q14 -> 3190 | S14: =R14-L14 -> 870
A15: CT/149 | B15: 53.000.661 WAGNER LUIZ BACKES MACHADO | C15: 5 - Foyer e restaurante | D15: Aditivo 3 | E15: 28/07/2026 | F15: 00.001.001.011 | G15: 80285 | H15: Desmonte da estrutura metálica existente com cobertura em acrílico, montagem da nova estrutura metálica para instalação da cobertura em telhas shingle, montagem da estrutura metálica de apoio para instalação dos vidros. | I15: vb | J15: 1 | K15: 3900 | L15: =J15*K15 -> 3900 | M15: =K15*(1+Parâmetros!$B$5) -> 5265 | N15: =J15*M15 -> 5265 | O15: =K15*(1+Parâmetros!$B$6) -> 5460 | P15: =J15*O15 -> 5460 | Q15: =K15*(1+Parâmetros!$B$7) -> 5362.5 | R15: =J15*Q15 -> 5362.5 | S15: =R15-L15 -> 1462.5
A16: CT/149 | B16: 53.000.661 WAGNER LUIZ BACKES MACHADO | C16: 5 - Foyer e restaurante | D16: Aditivo 3 | E16: 28/07/2026 | F16: 00.001.001.012 | G16: 80285 | H16: Ampliação da estrutura metálica na região do bico da cobertura para adequação às telhas shingle. | I16: vb | J16: 1 | K16: 2200 | L16: =J16*K16 -> 2200 | M16: =K16*(1+Parâmetros!$B$5) -> 2970 | N16: =J16*M16 -> 2970 | O16: =K16*(1+Parâmetros!$B$6) -> 3080 | P16: =J16*O16 -> 3080 | Q16: =K16*(1+Parâmetros!$B$7) -> 3025 | R16: =J16*Q16 -> 3025 | S16: =R16-L16 -> 825
A17: CT/149 | B17: 53.000.661 WAGNER LUIZ BACKES MACHADO | C17: 5 - Foyer e restaurante | D17: Aditivo 3 | E17: 28/07/2026 | F17: 00.001.001.013 | G17: 80285 | H17: Ampliação do beiral da cobertura em 0,70 m ao longo de 60,00 metros lineares, totalizando 42,00 m² de área adicional de cobertura, incluindo os ajustes necessários no beiral. | I17: vb | J17: 1 | K17: 3800 | L17: =J17*K17 -> 3800 | M17: =K17*(1+Parâmetros!$B$5) -> 5130 | N17: =J17*M17 -> 5130 | O17: =K17*(1+Parâmetros!$B$6) -> 5320 | P17: =J17*O17 -> 5320 | Q17: =K17*(1+Parâmetros!$B$7) -> 5225 | R17: =J17*Q17 -> 5225 | S17: =R17-L17 -> 1425
A18: CT/164 | B18: CAM EMPREITEIRA DE MAO DE OBRA LTDA | C18: 4 - Centro de eventos | D18: Inicial | F18: 00.000.001.001 | G18: 80407 | H18: Piso de concreto desempenado | I18: m² | J18: 2159.3 | K18: 15 | L18: =J18*K18 -> 32389.5 | M18: =K18*(1+Parâmetros!$B$5) -> 20.25 | N18: =J18*M18 -> 43725.825 | O18: =K18*(1+Parâmetros!$B$6) -> 21 | P18: =J18*O18 -> 45345.3 | Q18: =K18*(1+Parâmetros!$B$7) -> 20.625 | R18: =J18*Q18 -> 44535.562 | S18: =R18-L18 -> 12146.062
A19: CT/164 | B19: CAM EMPREITEIRA DE MAO DE OBRA LTDA | C19: 4 - Centro de eventos | D19: Inicial | F19: 00.000.001.002 | G19: 80408 | H19: Piso de concreto polido | I19: m² | J19: 8709.7 | K19: 18 | L19: =J19*K19 -> 156774.6 | M19: =K19*(1+Parâmetros!$B$5) -> 24.3 | N19: =J19*M19 -> 211645.71 | O19: =K19*(1+Parâmetros!$B$6) -> 25.2 | P19: =J19*O19 -> 219484.44 | Q19: =K19*(1+Parâmetros!$B$7) -> 24.75 | R19: =J19*Q19 -> 215565.08 | S19: =R19-L19 -> 58790.475
A20: CT/164 | B20: CAM EMPREITEIRA DE MAO DE OBRA LTDA | C20: 5 - Foyer e restaurante | D20: Inicial | F20: 00.001.001.001 | G20: 80321 | H20: Piso de concreto desempenado | I20: m² | J20: 2661.5 | K20: 15 | L20: =J20*K20 -> 39922.5 | M20: =K20*(1+Parâmetros!$B$5) -> 20.25 | N20: =J20*M20 -> 53895.375 | O20: =K20*(1+Parâmetros!$B$6) -> 21 | P20: =J20*O20 -> 55891.5 | Q20: =K20*(1+Parâmetros!$B$7) -> 20.625 | R20: =J20*Q20 -> 54893.438 | S20: =R20-L20 -> 14970.938
A21: CT/164 | B21: CAM EMPREITEIRA DE MAO DE OBRA LTDA | C21: 5 - Foyer e restaurante | D21: Inicial | F21: 00.002.001.001 | G21: 80321 | H21: Piso de concreto polido | I21: m² | J21: 709.5 | K21: 18 | L21: =J21*K21 -> 12771 | M21: =K21*(1+Parâmetros!$B$5) -> 24.3 | N21: =J21*M21 -> 17240.85 | O21: =K21*(1+Parâmetros!$B$6) -> 25.2 | P21: =J21*O21 -> 17879.4 | Q21: =K21*(1+Parâmetros!$B$7) -> 24.75 | R21: =J21*Q21 -> 17560.125 | S21: =R21-L21 -> 4789.125
A22: CT/164 | B22: CAM EMPREITEIRA DE MAO DE OBRA LTDA | C22: 4 - Centro de eventos | D22: Aditivo 1 | E22: 24/07/2026 | F22: 00.000.001.001 | G22: 80407 | H22: Piso de concreto desempenado | I22: m² | J22: 1982.43 | K22: 15 | L22: =J22*K22 -> 29736.45 | M22: =K22*(1+Parâmetros!$B$5) -> 20.25 | N22: =J22*M22 -> 40144.207 | O22: =K22*(1+Parâmetros!$B$6) -> 21 | P22: =J22*O22 -> 41631.03 | Q22: =K22*(1+Parâmetros!$B$7) -> 20.625 | R22: =J22*Q22 -> 40887.619 | S22: =R22-L22 -> 11151.169
A23: CT/164 | B23: CAM EMPREITEIRA DE MAO DE OBRA LTDA | C23: 4 - Centro de eventos | D23: Aditivo 1 | E23: 24/07/2026 | F23: 00.000.001.002 | G23: 80408 | H23: Piso de concreto polido | I23: m² | J23: 1393.32 | K23: 18 | L23: =J23*K23 -> 25079.76 | M23: =K23*(1+Parâmetros!$B$5) -> 24.3 | N23: =J23*M23 -> 33857.676 | O23: =K23*(1+Parâmetros!$B$6) -> 25.2 | P23: =J23*O23 -> 35111.664 | Q23: =K23*(1+Parâmetros!$B$7) -> 24.75 | R23: =J23*Q23 -> 34484.67 | S23: =R23-L23 -> 9404.91
A24: CT/196 | B24: ROSENILDE RODRIGUES LINDOLFO DE SOUZA | C24: 4 - Centro de eventos | D24: Inicial | F24: 00.001.001.001 | G24: 80388 | H24: Execução de parede em drywall, composta por estrutura simples em perfis metálicos galvanizados, com fechamento em chapas ST, incluindo montagem, fixação e acabamentos necessários. | I24: m² | J24: 500 | K24: 65 | L24: =J24*K24 -> 32500 | M24: =K24*(1+Parâmetros!$B$5) -> 87.75 | N24: =J24*M24 -> 43875 | O24: =K24*(1+Parâmetros!$B$6) -> 91 | P24: =J24*O24 -> 45500 | Q24: =K24*(1+Parâmetros!$B$7) -> 89.375 | R24: =J24*Q24 -> 44687.5 | S24: =R24-L24 -> 12187.5
A25: CT/196 | B25: ROSENILDE RODRIGUES LINDOLFO DE SOUZA | C25: 4 - Centro de eventos | D25: Aditivo 1 | E25: 03/07/2026 | F25: 00.001.001.001 | G25: 80388 | H25: Execução de parede em drywall, composta por estrutura simples em perfis metálicos galvanizados, com fechamento em chapas ST, incluindo montagem, fixação e acabamentos necessários. | I25: m² | J25: 700 | K25: 65 | L25: =J25*K25 -> 45500 | M25: =K25*(1+Parâmetros!$B$5) -> 87.75 | N25: =J25*M25 -> 61425 | O25: =K25*(1+Parâmetros!$B$6) -> 91 | P25: =J25*O25 -> 63700 | Q25: =K25*(1+Parâmetros!$B$7) -> 89.375 | R25: =J25*Q25 -> 62562.5 | S25: =R25-L25 -> 17062.5
A26: CT/196 | B26: ROSENILDE RODRIGUES LINDOLFO DE SOUZA | C26: 4 - Centro de eventos | D26: Aditivo 2 | E26: 31/07/2026 | F26: 00.001.001.001 | G26: 80388 | H26: Execução de parede em drywall, composta por estrutura simples em perfis metálicos galvanizados, com fechamento em chapas ST, incluindo montagem, fixação e acabamentos necessários. | I26: m² | J26: 203.75 | K26: 65 | L26: =J26*K26 -> 13243.75 | M26: =K26*(1+Parâmetros!$B$5) -> 87.75 | N26: =J26*M26 -> 17879.062 | O26: =K26*(1+Parâmetros!$B$6) -> 91 | P26: =J26*O26 -> 18541.25 | Q26: =K26*(1+Parâmetros!$B$7) -> 89.375 | R26: =J26*Q26 -> 18210.156 | S26: =R26-L26 -> 4966.4062
A27: CT/196 | B27: ROSENILDE RODRIGUES LINDOLFO DE SOUZA | C27: 4 - Centro de eventos | D27: Aditivo 2 | E27: 31/07/2026 | F27: 00.001.001.002 | G27: 80362 | H27: Execução de requadros em gesso acartonado. | I27: m | J27: 301.2 | K27: 20 | L27: =J27*K27 -> 6024 | M27: =K27*(1+Parâmetros!$B$5) -> 27 | N27: =J27*M27 -> 8132.4 | O27: =K27*(1+Parâmetros!$B$6) -> 28 | P27: =J27*O27 -> 8433.6 | Q27: =K27*(1+Parâmetros!$B$7) -> 27.5 | R27: =J27*Q27 -> 8283 | S27: =R27-L27 -> 2259
A28: CT/196 | B28: ROSENILDE RODRIGUES LINDOLFO DE SOUZA | C28: 4 - Centro de eventos | D28: Aditivo 2 | E28: 31/07/2026 | F28: 00.001.001.003 | G28: 80388 | H28: Execução de forro em gesso acartonado. | I28: m² | J28: 317.77 | K28: 30 | L28: =J28*K28 -> 9533.1 | M28: =K28*(1+Parâmetros!$B$5) -> 40.5 | N28: =J28*M28 -> 12869.685 | O28: =K28*(1+Parâmetros!$B$6) -> 42 | P28: =J28*O28 -> 13346.34 | Q28: =K28*(1+Parâmetros!$B$7) -> 41.25 | R28: =J28*Q28 -> 13108.013 | S28: =R28-L28 -> 3574.9125
A29: CT/196 | B29: ROSENILDE RODRIGUES LINDOLFO DE SOUZA | C29: 4 - Centro de eventos | D29: Aditivo 2 | E29: 31/07/2026 | F29: 00.001.001.004 | G29: 80388 | H29: Execução de paredes em Steelframe com MDF. | I29: m² | J29: 253.46 | K29: 70 | L29: =J29*K29 -> 17742.2 | M29: =K29*(1+Parâmetros!$B$5) -> 94.5 | N29: =J29*M29 -> 23951.97 | O29: =K29*(1+Parâmetros!$B$6) -> 98 | P29: =J29*O29 -> 24839.08 | Q29: =K29*(1+Parâmetros!$B$7) -> 96.25 | R29: =J29*Q29 -> 24395.525 | S29: =R29-L29 -> 6653.325
A30: CT/212 | B30: AGR DELAVI PISOS LTDA | C30: 4 - Centro de eventos | D30: Inicial | F30: 00.001.001.001 | G30: 80409 | H30: Execução de piso fulget. | I30: m² | J30: 1199.04 | K30: 80 | L30: =J30*K30 -> 95923.2 | M30: =K30*(1+Parâmetros!$B$5) -> 108 | N30: =J30*M30 -> 129496.32 | O30: =K30*(1+Parâmetros!$B$6) -> 112 | P30: =J30*O30 -> 134292.48 | Q30: =K30*(1+Parâmetros!$B$7) -> 110 | R30: =J30*Q30 -> 131894.4 | S30: =R30-L30 -> 35971.2
A31: CT/216 | B31: LOURIVAL BONFIM 66371490982 | C31: 4 - Centro de eventos | D31: Inicial | F31: 00.001.001.001 | G31: 80391 | H31: Execução do revestimento em ACM na região do porte-cochère do Centro de Eventos do Hotel Recanto. | I31: vb | J31: 1 | K31: 60000 | L31: =J31*K31 -> 60000 | M31: =K31*(1+Parâmetros!$B$5) -> 81000 | N31: =J31*M31 -> 81000 | O31: =K31*(1+Parâmetros!$B$6) -> 84000 | P31: =J31*O31 -> 84000 | Q31: =K31*(1+Parâmetros!$B$7) -> 82500 | R31: =J31*Q31 -> 82500 | S31: =R31-L31 -> 22500
A32: CT/216 | B32: LOURIVAL BONFIM 66371490982 | C32: 4 - Centro de eventos | D32: Aditivo 1 | E32: 17/08/2026 | F32: 00.001.001.002 | G32: 80391 | H32: Execução do painel de 60x90 cm sobre a porta do Centro de Eventos, execução de forro em ACM com dimensões de 50x2,40 m, fechamento da porta com dimensões de 4,80x2,40 m e execução das divisórias dos banheiros. | I32: vb | J32: 1 | K32: 37671 | L32: =J32*K32 -> 37671 | M32: =K32*(1+Parâmetros!$B$5) -> 50855.85 | N32: =J32*M32 -> 50855.85 | O32: =K32*(1+Parâmetros!$B$6) -> 52739.4 | P32: =J32*O32 -> 52739.4 | Q32: =K32*(1+Parâmetros!$B$7) -> 51797.625 | R32: =J32*Q32 -> 51797.625 | S32: =R32-L32 -> 14126.625
A33: CT/217 | B33: 60.623.714 VALDEMIR MENDES DA SILVA | C33: 5 - Foyer e restaurante | D33: Inicial | F33: 00.001.001.001 | G33: 80309 | H33: Execução de parede em gesso acartonado (drywall), compreendendo o fornecimento e montagem da estrutura metálica de perfilação, instalação de isolamento em lã acústica e fixação das placas de gesso acartonado. | I33: m² | J33: 62.83 | K33: 55 | L33: =J33*K33 -> 3455.65 | M33: =K33*(1+Parâmetros!$B$5) -> 74.25 | N33: =J33*M33 -> 4665.1275 | O33: =K33*(1+Parâmetros!$B$6) -> 77 | P33: =J33*O33 -> 4837.91 | Q33: =K33*(1+Parâmetros!$B$7) -> 75.625 | R33: =J33*Q33 -> 4751.5188 | S33: =R33-L33 -> 1295.8688
A34: CT/217 | B34: 60.623.714 VALDEMIR MENDES DA SILVA | C34: 5 - Foyer e restaurante | D34: Inicial | F34: 00.002.001.001 | G34: 80319 | H34: Execução de sanca em gesso acartonado. | I34: m² | J34: 220 | K34: 60 | L34: =J34*K34 -> 13200 | M34: =K34*(1+Parâmetros!$B$5) -> 81 | N34: =J34*M34 -> 17820 | O34: =K34*(1+Parâmetros!$B$6) -> 84 | P34: =J34*O34 -> 18480 | Q34: =K34*(1+Parâmetros!$B$7) -> 82.5 | R34: =J34*Q34 -> 18150 | S34: =R34-L34 -> 4950
A35: CT/217 | B35: 60.623.714 VALDEMIR MENDES DA SILVA | C35: 5 - Foyer e restaurante | D35: Inicial | F35: 00.002.001.002 | G35: 80319 | H35: Desmanche de forro em gesso acartonado na região do Foyer. | I35: m² | J35: 30 | K35: 20 | L35: =J35*K35 -> 600 | M35: =K35*(1+Parâmetros!$B$5) -> 27 | N35: =J35*M35 -> 810 | O35: =K35*(1+Parâmetros!$B$6) -> 28 | P35: =J35*O35 -> 840 | Q35: =K35*(1+Parâmetros!$B$7) -> 27.5 | R35: =J35*Q35 -> 825 | S35: =R35-L35 -> 225
A36: CT/217 | B36: 60.623.714 VALDEMIR MENDES DA SILVA | C36: 5 - Foyer e restaurante | D36: Inicial | F36: 00.002.001.003 | G36: 80319 | H36: Execução de forro em gesso acartonado, incluindo execução de sanca. | I36: m² | J36: 115 | K36: 50 | L36: =J36*K36 -> 5750 | M36: =K36*(1+Parâmetros!$B$5) -> 67.5 | N36: =J36*M36 -> 7762.5 | O36: =K36*(1+Parâmetros!$B$6) -> 70 | P36: =J36*O36 -> 8050 | Q36: =K36*(1+Parâmetros!$B$7) -> 68.75 | R36: =J36*Q36 -> 7906.25 | S36: =R36-L36 -> 2156.25
A37: CT/217 | B37: 60.623.714 VALDEMIR MENDES DA SILVA | C37: 5 - Foyer e restaurante | D37: Inicial | F37: 00.002.001.004 | G37: 80287 | H37: Execução de fechamento do portal do elevador. | I37: unid | J37: 2 | K37: 300 | L37: =J37*K37 -> 600 | M37: =K37*(1+Parâmetros!$B$5) -> 405 | N37: =J37*M37 -> 810 | O37: =K37*(1+Parâmetros!$B$6) -> 420 | P37: =J37*O37 -> 840 | Q37: =K37*(1+Parâmetros!$B$7) -> 412.5 | R37: =J37*Q37 -> 825 | S37: =R37-L37 -> 225
A38: CT/217 | B38: 60.623.714 VALDEMIR MENDES DA SILVA | C38: 5 - Foyer e restaurante | D38: Aditivo 1 | E38: 19/08/2026 | F38: 00.001.001.001 | G38: 80309 | H38: Execução de parede em gesso acartonado (drywall), compreendendo o fornecimento e montagem da estrutura metálica de perfilação, instalação de isolamento em lã acústica e fixação das placas de gesso acartonado. | I38: m² | J38: 13 | K38: 55 | L38: =J38*K38 -> 715 | M38: =K38*(1+Parâmetros!$B$5) -> 74.25 | N38: =J38*M38 -> 965.25 | O38: =K38*(1+Parâmetros!$B$6) -> 77 | P38: =J38*O38 -> 1001 | Q38: =K38*(1+Parâmetros!$B$7) -> 75.625 | R38: =J38*Q38 -> 983.125 | S38: =R38-L38 -> 268.125
A39: CT/217 | B39: 60.623.714 VALDEMIR MENDES DA SILVA | C39: 5 - Foyer e restaurante | D39: Aditivo 1 | E39: 19/08/2026 | F39: 00.002.001.003 | G39: 80319 | H39: Execução de forro em gesso acartonado, incluindo execução de sanca. | I39: m² | J39: 10 | K39: 50 | L39: =J39*K39 -> 500 | M39: =K39*(1+Parâmetros!$B$5) -> 67.5 | N39: =J39*M39 -> 675 | O39: =K39*(1+Parâmetros!$B$6) -> 70 | P39: =J39*O39 -> 700 | Q39: =K39*(1+Parâmetros!$B$7) -> 68.75 | R39: =J39*Q39 -> 687.5 | S39: =R39-L39 -> 187.5
A40: CT/217 | B40: 60.623.714 VALDEMIR MENDES DA SILVA | C40: 5 - Foyer e restaurante | D40: Aditivo 1 | E40: 19/08/2026 | F40: 00.002.001.005 | G40: 80274 | H40: Fechamento em glassrock, parede externa do Foyer da Torre. | I40: vb | J40: 1 | K40: 700 | L40: =J40*K40 -> 700 | M40: =K40*(1+Parâmetros!$B$5) -> 945 | N40: =J40*M40 -> 945 | O40: =K40*(1+Parâmetros!$B$6) -> 980 | P40: =J40*O40 -> 980 | Q40: =K40*(1+Parâmetros!$B$7) -> 962.5 | R40: =J40*Q40 -> 962.5 | S40: =R40-L40 -> 262.5
A42: TOTAL GERAL | L42: =SUM(L5:L40) -> 850591.71 | N42: =SUM(N5:N40) -> 1148298.8 | P42: =SUM(P5:P40) -> 1190828.4 | R42: =SUM(R5:R40) -> 1169563.6 | S42: =SUM(S5:S40) -> 318971.89

Sheet CT-149
A1: CT/149 — 53.000.661 WAGNER LUIZ BACKES MACHADO
A2: Arquivo de origem: CT149__Wagner_Backes__R00.pdf | Obra: 40200 - Empreita Recanto Cataratas Thermas Resort
A4: CNPJ do fornecedor | D4: 53.000.661/0001-83
A5: Data do contrato | D5: 17/12/2025
A6: Vigência | D6: 12/12/2025 a 12/03/2026
A7: Tipo de contrato | D7: 4 - SEM RETENÇÃO
A8: Objeto | D8: Fornecimento de mão de obra estrutura metálica doca maestra.
A9: Impostos / retenção | D9: INSS SOBRE AUTÔNOMO — apresentar guias 0% * 0% sobre mão de obra
A11: ADITIVOS
A12: Aditivo 1 — 31/03/2026 | D12: Cobertura metálica, montagem e instalação de telhas, incluso rufos e calhas. Remoção completa de letreiro, ACM e estrutura metálica. Aplicação de fundo anti ferrugem em todas as peças (não estão inclusos itens abrasivos, somente mão de obra). Será necessário o uso de Munck.
A13: Aditivo 2 — 03/07/2026 | D13: Cobertura metálica com área aproximada de 185 m² para telhado tipo shingle, incluindo limpeza e aplicação de fundo anti ferrugem na estrutura metálica, ampliação da estrutura, fechamento com 153 m de telha de zinco, instalação de 221 m de rufos (entre pingadeiras e algerosas), desmontagem de estrutura metálica e revestimento em ACM, e fabricação e instalação de suporte metálico para bobina de fio.
A14: Aditivo 3 — 28/07/2026 | D14: Fabricação e instalação de 60,00 m lineares de calha mestra e 58,00 m lineares de rufo, incluindo vedação dupla entre a laje destinada aos aparelhos de ar-condicionado e a cobertura em telhas shingle. Compreende ainda o desmonte da estrutura metálica existente com cobertura em acrílico, montagem da nova estrutura, montagem da estrutura de apoio para instalação dos vidros, ampliação na região do bico da cobertura e ampliação do beiral em 0,70 m ao longo de 60,00 m (42,00 m² adicionais).
A16: Origem | B16: Data do aditivo | C16: Unid. construtiva | D16: Referência | E16: Código | F16: Descrição | G16: Un. | H16: Quantidade | I16: Vl. unit. original | J16: Total original | K16: Vl. unit. +35% | L16: Total +35% | M16: Vl. unit. +40% | N16: Total +40% | O16: Vl. unit. aplicado | P16: Total aplicado
A17: =IF('Itens Consolidados'!D5="","",'Itens Consolidados'!D5) -> Inicial | B17: =IF('Itens Consolidados'!E5="","",'Itens Consolidados'!E5) | C17: =IF('Itens Consolidados'!C5="","",'Itens Consolidados'!C5) -> 5 - Foyer e restaurante | D17: =IF('Itens Consolidados'!F5="","",'Itens Consolidados'!F5) -> 00.001.001.001 | E17: =IF('Itens Consolidados'!G5="","",'Itens Consolidados'!G5) -> 80285 | F17: =IF('Itens Consolidados'!H5="","",'Itens Consolidados'!H5) -> Estrutura metálica, escoramento e telhado doca | G17: =IF('Itens Consolidados'!I5="","",'Itens Consolidados'!I5) -> vb | H17: ='Itens Consolidados'!J5 -> 1 | I17: ='Itens Consolidados'!K5 -> 42000 | J17: ='Itens Consolidados'!L5 -> 42000 | K17: ='Itens Consolidados'!M5 -> 56700 | L17: ='Itens Consolidados'!N5 -> 56700 | M17: ='Itens Consolidados'!O5 -> 58800 | N17: ='Itens Consolidados'!P5 -> 58800 | O17: ='Itens Consolidados'!Q5 -> 57750 | P17: ='Itens Consolidados'!R5 -> 57750
A18: Total dos itens iniciais | J18: =SUM(J17:J17) -> 42000 | L18: =SUM(L17:L17) -> 56700 | N18: =SUM(N17:N17) -> 58800 | P18: =SUM(P17:P17) -> 57750
A19: =IF('Itens Consolidados'!D6="","",'Itens Consolidados'!D6) -> Aditivo 1 | B19: =IF('Itens Consolidados'!E6="","",'Itens Consolidados'!E6) -> 31/03/2026 | C19: =IF('Itens Consolidados'!C6="","",'Itens Consolidados'!C6) -> 5 - Foyer e restaurante | D19: =IF('Itens Consolidados'!F6="","",'Itens Consolidados'!F6) -> 00.001.001.002 | E19: =IF('Itens Consolidados'!G6="","",'Itens Consolidados'!G6) -> 80285 | F19: =IF('Itens Consolidados'!H6="","",'Itens Consolidados'!H6) -> Execução de cobertura lateral de 344,35 m², incluindo montagem da estrutura metálica, instalação de telhas com rufos e calhas. Aplicação de fundo anti ferrugem em todas as peças. | G19: =IF('Itens Consolidados'!I6="","",'Itens Consolidados'!I6) -> vb | H19: ='Itens Consolidados'!J6 -> 1 | I19: ='Itens Consolidados'!K6 -> 51300 | J19: ='Itens Consolidados'!L6 -> 51300 | K19: ='Itens Consolidados'!M6 -> 69255 | L19: ='Itens Consolidados'!N6 -> 69255 | M19: ='Itens Consolidados'!O6 -> 71820 | N19: ='Itens Consolidados'!P6 -> 71820 | O19: ='Itens Consolidados'!Q6 -> 70537.5 | P19: ='Itens Consolidados'!R6 -> 70537.5
A20: =IF('Itens Consolidados'!D7="","",'Itens Consolidados'!D7) -> Aditivo 1 | B20: =IF('Itens Consolidados'!E7="","",'Itens Consolidados'!E7) -> 31/03/2026 | C20: =IF('Itens Consolidados'!C7="","",'Itens Consolidados'!C7) -> 5 - Foyer e restaurante | D20: =IF('Itens Consolidados'!F7="","",'Itens Consolidados'!F7) -> 00.001.001.003 | E20: =IF('Itens Consolidados'!G7="","",'Itens Consolidados'!G7) -> 80285 | F20: =IF('Itens Consolidados'!H7="","",'Itens Consolidados'!H7) -> Execução de cobertura lateral de 212 m², parte métrica montada com rufos e calhas, incluindo remoção de 02 bicos metálicos. Aplicação de fundo anti ferrugem em todas as peças. | G20: =IF('Itens Consolidados'!I7="","",'Itens Consolidados'!I7) -> vb | H20: ='Itens Consolidados'!J7 -> 1 | I20: ='Itens Consolidados'!K7 -> 26600 | J20: ='Itens Consolidados'!L7 -> 26600 | K20: ='Itens Consolidados'!M7 -> 35910 | L20: ='Itens Consolidados'!N7 -> 35910 | M20: ='Itens Consolidados'!O7 -> 37240 | N20: ='Itens Consolidados'!P7 -> 37240 | O20: ='Itens Consolidados'!Q7 -> 36575 | P20: ='Itens Consolidados'!R7 -> 36575
A21: =IF('Itens Consolidados'!D8="","",'Itens Consolidados'!D8) -> Aditivo 1 | B21: =IF('Itens Consolidados'!E8="","",'Itens Consolidados'!E8) -> 31/03/2026 | C21: =IF('Itens Consolidados'!C8="","",'Itens Consolidados'!C8) -> 5 - Foyer e restaurante | D21: =IF('Itens Consolidados'!F8="","",'Itens Consolidados'!F8) -> 00.001.001.004 | E21: =IF('Itens Consolidados'!G8="","",'Itens Consolidados'!G8) -> 80285 | F21: =IF('Itens Consolidados'!H8="","",'Itens Consolidados'!H8) -> Remoção de estrutura metálica com fachada em ACM, remoção completa de letreiro, ACM e estrutura metálica. | G21: =IF('Itens Consolidados'!I8="","",'Itens Consolidados'!I8) -> vb | H21: ='Itens Consolidados'!J8 -> 1 | I21: ='Itens Consolidados'!K8 -> 10500 | J21: ='Itens Consolidados'!L8 -> 10500 | K21: ='Itens Consolidados'!M8 -> 14175 | L21: ='Itens Consolidados'!N8 -> 14175 | M21: ='Itens Consolidados'!O8 -> 14700 | N21: ='Itens Consolidados'!P8 -> 14700 | O21: ='Itens Consolidados'!Q8 -> 14437.5 | P21: ='Itens Consolidados'!R8 -> 14437.5
A22: Total do aditivo 1 | J22: =SUM(J19:J21) -> 88400 | L22: =SUM(L19:L21) -> 119340 | N22: =SUM(N19:N21) -> 123760 | P22: =SUM(P19:P21) -> 121550
A23: =IF('Itens Consolidados'!D9="","",'Itens Consolidados'!D9) -> Aditivo 2 | B23: =IF('Itens Consolidados'!E9="","",'Itens Consolidados'!E9) -> 03/07/2026 | C23: =IF('Itens Consolidados'!C9="","",'Itens Consolidados'!C9) -> 5 - Foyer e restaurante | D23: =IF('Itens Consolidados'!F9="","",'Itens Consolidados'!F9) -> 00.001.001.005 | E23: =IF('Itens Consolidados'!G9="","",'Itens Consolidados'!G9) -> 80285 | F23: =IF('Itens Consolidados'!H9="","",'Itens Consolidados'!H9) -> Execução de cobertura metálica para telhado tipo shingle, incluindo adequação e tratamento anticorrosivo da estrutura, fechamento com telha de zinco, instalação de rufos, desmontagem de estrutura metálica e fabricação de suporte metálico. | G23: =IF('Itens Consolidados'!I9="","",'Itens Consolidados'!I9) -> vb | H23: ='Itens Consolidados'!J9 -> 1 | I23: ='Itens Consolidados'!K9 -> 40000 | J23: ='Itens Consolidados'!L9 -> 40000 | K23: ='Itens Consolidados'!M9 -> 54000 | L23: ='Itens Consolidados'!N9 -> 54000 | M23: ='Itens Consolidados'!O9 -> 56000 | N23: ='Itens Consolidados'!P9 -> 56000 | O23: ='Itens Consolidados'!Q9 -> 55000 | P23: ='Itens Consolidados'!R9 -> 55000
A24: =IF('Itens Consolidados'!D10="","",'Itens Consolidados'!D10) -> Aditivo 2 | B24: =IF('Itens Consolidados'!E10="","",'Itens Consolidados'!E10) -> 03/07/2026 | C24: =IF('Itens Consolidados'!C10="","",'Itens Consolidados'!C10) -> 5 - Foyer e restaurante | D24: =IF('Itens Consolidados'!F10="","",'Itens Consolidados'!F10) -> 00.001.001.006 | E24: =IF('Itens Consolidados'!G10="","",'Itens Consolidados'!G10) -> 80285 | F24: =IF('Itens Consolidados'!H10="","",'Itens Consolidados'!H10) -> Ajuste na calha do Hermes; foi feita uma nova dobragem na calha. | G24: =IF('Itens Consolidados'!I10="","",'Itens Consolidados'!I10) -> vb | H24: ='Itens Consolidados'!J10 -> 1 | I24: ='Itens Consolidados'!K10 -> 1200 | J24: ='Itens Consolidados'!L10 -> 1200 | K24: ='Itens Consolidados'!M10 -> 1620 | L24: ='Itens Consolidados'!N10 -> 1620 | M24: ='Itens Consolidados'!O10 -> 1680 | N24: ='Itens Consolidados'!P10 -> 1680 | O24: ='Itens Consolidados'!Q10 -> 1650 | P24: ='Itens Consolidados'!R10 -> 1650
A25: =IF('Itens Consolidados'!D11="","",'Itens Consolidados'!D11) -> Aditivo 2 | B25: =IF('Itens Consolidados'!E11="","",'Itens Consolidados'!E11) -> 03/07/2026 | C25: =IF('Itens Consolidados'!C11="","",'Itens Consolidados'!C11) -> 5 - Foyer e restaurante | D25: =IF('Itens Consolidados'!F11="","",'Itens Consolidados'!F11) -> 00.001.001.007 | E25: =IF('Itens Consolidados'!G11="","",'Itens Consolidados'!G11) -> 80285 | F25: =IF('Itens Consolidados'!H11="","",'Itens Consolidados'!H11) -> Execução do fechamento lateral centro de eventos. | G25: =IF('Itens Consolidados'!I11="","",'Itens Consolidados'!I11) -> vb | H25: ='Itens Consolidados'!J11 -> 1 | I25: ='Itens Consolidados'!K11 -> 14340 | J25: ='Itens Consolidados'!L11 -> 14340 | K25: ='Itens Consolidados'!M11 -> 19359 | L25: ='Itens Consolidados'!N11 -> 19359 | M25: ='Itens Consolidados'!O11 -> 20076 | N25: ='Itens Consolidados'!P11 -> 20076 | O25: ='Itens Consolidados'!Q11 -> 19717.5 | P25: ='Itens Consolidados'!R11 -> 19717.5
A26: =IF('Itens Consolidados'!D12="","",'Itens Consolidados'!D12) -> Aditivo 2 | B26: =IF('Itens Consolidados'!E12="","",'Itens Consolidados'!E12) -> 03/07/2026 | C26: =IF('Itens Consolidados'!C12="","",'Itens Consolidados'!C12) -> 5 - Foyer e restaurante | D26: =IF('Itens Consolidados'!F12="","",'Itens Consolidados'!F12) -> 00.001.001.008 | E26: =IF('Itens Consolidados'!G12="","",'Itens Consolidados'!G12) -> 80285 | F26: =IF('Itens Consolidados'!H12="","",'Itens Consolidados'!H12) -> Preparação das terças para receber uma nova calha, execução de rufo entre o Vivace e Maestra. | G26: =IF('Itens Consolidados'!I12="","",'Itens Consolidados'!I12) -> vb | H26: ='Itens Consolidados'!J12 -> 1 | I26: ='Itens Consolidados'!K12 -> 4900 | J26: ='Itens Consolidados'!L12 -> 4900 | K26: ='Itens Consolidados'!M12 -> 6615 | L26: ='Itens Consolidados'!N12 -> 6615 | M26: ='Itens Consolidados'!O12 -> 6860 | N26: ='Itens Consolidados'!P12 -> 6860 | O26: ='Itens Consolidados'!Q12 -> 6737.5 | P26: ='Itens Consolidados'!R12 -> 6737.5
A27: Total do aditivo 2 | J27: =SUM(J23:J26) -> 60440 | L27: =SUM(L23:L26) -> 81594 | N27: =SUM(N23:N26) -> 84616 | P27: =SUM(P23:P26) -> 83105
A28: =IF('Itens Consolidados'!D13="","",'Itens Consolidados'!D13) -> Aditivo 3 | B28: =IF('Itens Consolidados'!E13="","",'Itens Consolidados'!E13) -> 28/07/2026 | C28: =IF('Itens Consolidados'!C13="","",'Itens Consolidados'!C13) -> 5 - Foyer e restaurante | D28: =IF('Itens Consolidados'!F13="","",'Itens Consolidados'!F13) -> 00.001.001.009 | E28: =IF('Itens Consolidados'!G13="","",'Itens Consolidados'!G13) -> 80285 | F28: =IF('Itens Consolidados'!H13="","",'Itens Consolidados'!H13) -> Fabricação e instalação de 60 m de calha — Maestra. | G28: =IF('Itens Consolidados'!I13="","",'Itens Consolidados'!I13) -> vb | H28: ='Itens Consolidados'!J13 -> 1 | I28: ='Itens Consolidados'!K13 -> 7200 | J28: ='Itens Consolidados'!L13 -> 7200 | K28: ='Itens Consolidados'!M13 -> 9720 | L28: ='Itens Consolidados'!N13 -> 9720 | M28: ='Itens Consolidados'!O13 -> 10080 | N28: ='Itens Consolidados'!P13 -> 10080 | O28: ='Itens Consolidados'!Q13 -> 9900 | P28: ='Itens Consolidados'!R13 -> 9900
A29: =IF('Itens Consolidados'!D14="","",'Itens Consolidados'!D14) -> Aditivo 3 | B29: =IF('Itens Consolidados'!E14="","",'Itens Consolidados'!E14) -> 28/07/2026 | C29: =IF('Itens Consolidados'!C14="","",'Itens Consolidados'!C14) -> 5 - Foyer e restaurante | D29: =IF('Itens Consolidados'!F14="","",'Itens Consolidados'!F14) -> 00.001.001.010 | E29: =IF('Itens Consolidados'!G14="","",'Itens Consolidados'!G14) -> 80285 | F29: =IF('Itens Consolidados'!H14="","",'Itens Consolidados'!H14) -> Fabricação e instalação de 58,00 metros lineares de rufo, incluindo vedação dupla entre a laje destinada aos aparelhos de ar-condicionado e a cobertura em telhas shingle. | G29: =IF('Itens Consolidados'!I14="","",'Itens Consolidados'!I14) -> vb | H29: ='Itens Consolidados'!J14 -> 1 | I29: ='Itens Consolidados'!K14 -> 2320 | J29: ='Itens Consolidados'!L14 -> 2320 | K29: ='Itens Consolidados'!M14 -> 3132 | L29: ='Itens Consolidados'!N14 -> 3132 | M29: ='Itens Consolidados'!O14 -> 3248 | N29: ='Itens Consolidados'!P14 -> 3248 | O29: ='Itens Consolidados'!Q14 -> 3190 | P29: ='Itens Consolidados'!R14 -> 3190
A30: =IF('Itens Consolidados'!D15="","",'Itens Consolidados'!D15) -> Aditivo 3 | B30: =IF('Itens Consolidados'!E15="","",'Itens Consolidados'!E15) -> 28/07/2026 | C30: =IF('Itens Consolidados'!C15="","",'Itens Consolidados'!C15) -> 5 - Foyer e restaurante | D30: =IF('Itens Consolidados'!F15="","",'Itens Consolidados'!F15) -> 00.001.001.011 | E30: =IF('Itens Consolidados'!G15="","",'Itens Consolidados'!G15) -> 80285 | F30: =IF('Itens Consolidados'!H15="","",'Itens Consolidados'!H15) -> Desmonte da estrutura metálica existente com cobertura em acrílico, montagem da nova estrutura metálica para instalação da cobertura em telhas shingle, montagem da estrutura metálica de apoio para instalação dos vidros. | G30: =IF('Itens Consolidados'!I15="","",'Itens Consolidados'!I15) -> vb | H30: ='Itens Consolidados'!J15 -> 1 | I30: ='Itens Consolidados'!K15 -> 3900 | J30: ='Itens Consolidados'!L15 -> 3900 | K30: ='Itens Consolidados'!M15 -> 5265 | L30: ='Itens Consolidados'!N15 -> 5265 | M30: ='Itens Consolidados'!O15 -> 5460 | N30: ='Itens Consolidados'!P15 -> 5460 | O30: ='Itens Consolidados'!Q15 -> 5362.5 | P30: ='Itens Consolidados'!R15 -> 5362.5
A31: =IF('Itens Consolidados'!D16="","",'Itens Consolidados'!D16) -> Aditivo 3 | B31: =IF('Itens Consolidados'!E16="","",'Itens Consolidados'!E16) -> 28/07/2026 | C31: =IF('Itens Consolidados'!C16="","",'Itens Consolidados'!C16) -> 5 - Foyer e restaurante | D31: =IF('Itens Consolidados'!F16="","",'Itens Consolidados'!F16) -> 00.001.001.012 | E31: =IF('Itens Consolidados'!G16="","",'Itens Consolidados'!G16) -> 80285 | F31: =IF('Itens Consolidados'!H16="","",'Itens Consolidados'!H16) -> Ampliação da estrutura metálica na região do bico da cobertura para adequação às telhas shingle. | G31: =IF('Itens Consolidados'!I16="","",'Itens Consolidados'!I16) -> vb | H31: ='Itens Consolidados'!J16 -> 1 | I31: ='Itens Consolidados'!K16 -> 2200 | J31: ='Itens Consolidados'!L16 -> 2200 | K31: ='Itens Consolidados'!M16 -> 2970 | L31: ='Itens Consolidados'!N16 -> 2970 | M31: ='Itens Consolidados'!O16 -> 3080 | N31: ='Itens Consolidados'!P16 -> 3080 | O31: ='Itens Consolidados'!Q16 -> 3025 | P31: ='Itens Consolidados'!R16 -> 3025
A32: =IF('Itens Consolidados'!D17="","",'Itens Consolidados'!D17) -> Aditivo 3 | B32: =IF('Itens Consolidados'!E17="","",'Itens Consolidados'!E17) -> 28/07/2026 | C32: =IF('Itens Consolidados'!C17="","",'Itens Consolidados'!C17) -> 5 - Foyer e restaurante | D32: =IF('Itens Consolidados'!F17="","",'Itens Consolidados'!F17) -> 00.001.001.013 | E32: =IF('Itens Consolidados'!G17="","",'Itens Consolidados'!G17) -> 80285 | F32: =IF('Itens Consolidados'!H17="","",'Itens Consolidados'!H17) -> Ampliação do beiral da cobertura em 0,70 m ao longo de 60,00 metros lineares, totalizando 42,00 m² de área adicional de cobertura, incluindo os ajustes necessários no beiral. | G32: =IF('Itens Consolidados'!I17="","",'Itens Consolidados'!I17) -> vb | H32: ='Itens Consolidados'!J17 -> 1 | I32: ='Itens Consolidados'!K17 -> 3800 | J32: ='Itens Consolidados'!L17 -> 3800 | K32: ='Itens Consolidados'!M17 -> 5130 | L32: ='Itens Consolidados'!N17 -> 5130 | M32: ='Itens Consolidados'!O17 -> 5320 | N32: ='Itens Consolidados'!P17 -> 5320 | O32: ='Itens Consolidados'!Q17 -> 5225 | P32: ='Itens Consolidados'!R17 -> 5225
A33: Total do aditivo 3 | J33: =SUM(J28:J32) -> 19420 | L33: =SUM(L28:L32) -> 26217 | N33: =SUM(N28:N32) -> 27188 | P33: =SUM(P28:P32) -> 26702.5
A34: TOTAL DO CONTRATO CT/149 | J34: =J18+J22+J27+J33 -> 210260 | L34: =L18+L22+L27+L33 -> 283851 | N34: =N18+N22+N27+N33 -> 294364 | P34: =P18+P22+P27+P33 -> 289107.5
A35: Acréscimo gerado pelo markup aplicado | P35: =P34-J34 -> 78847.5

Sheet CT-164
A1: CT/164 — CAM EMPREITEIRA DE MAO DE OBRA LTDA
A2: Arquivo de origem: CT164__CAM_PISOS__R00.pdf | Obra: 40200 - Empreita Recanto Cataratas Thermas Resort
A4: CNPJ do fornecedor | D4: 01.128.174/0001-05
A5: Data do contrato | D5: 27/02/2026
A6: Vigência | D6: 03/01/2026 a 30/06/2026
A7: Tipo de contrato | D7: 4 - SEM RETENÇÃO
A8: Objeto | D8: Realizar o polimento mecanizado de piso e lajes de concreto.
A9: Impostos / retenção | D9: INSS S/PROLABORE — apresentar guias 100% * 0% sobre mão de obra
A11: ADITIVOS
A12: Aditivo 1 — 24/07/2026 | D12: Execução de piso polido: 1.393,32 m²; execução de piso desempenado: 1.982,43 m².
A14: Origem | B14: Data do aditivo | C14: Unid. construtiva | D14: Referência | E14: Código | F14: Descrição | G14: Un. | H14: Quantidade | I14: Vl. unit. original | J14: Total original | K14: Vl. unit. +35% | L14: Total +35% | M14: Vl. unit. +40% | N14: Total +40% | O14: Vl. unit. aplicado | P14: Total aplicado
A15: =IF('Itens Consolidados'!D18="","",'Itens Consolidados'!D18) -> Inicial | B15: =IF('Itens Consolidados'!E18="","",'Itens Consolidados'!E18) | C15: =IF('Itens Consolidados'!C18="","",'Itens Consolidados'!C18) -> 4 - Centro de eventos | D15: =IF('Itens Consolidados'!F18="","",'Itens Consolidados'!F18) -> 00.000.001.001 | E15: =IF('Itens Consolidados'!G18="","",'Itens Consolidados'!G18) -> 80407 | F15: =IF('Itens Consolidados'!H18="","",'Itens Consolidados'!H18) -> Piso de concreto desempenado | G15: =IF('Itens Consolidados'!I18="","",'Itens Consolidados'!I18) -> m² | H15: ='Itens Consolidados'!J18 -> 2159.3 | I15: ='Itens Consolidados'!K18 -> 15 | J15: ='Itens Consolidados'!L18 -> 32389.5 | K15: ='Itens Consolidados'!M18 -> 20.25 | L15: ='Itens Consolidados'!N18 -> 43725.825 | M15: ='Itens Consolidados'!O18 -> 21 | N15: ='Itens Consolidados'!P18 -> 45345.3 | O15: ='Itens Consolidados'!Q18 -> 20.625 | P15: ='Itens Consolidados'!R18 -> 44535.562
A16: =IF('Itens Consolidados'!D19="","",'Itens Consolidados'!D19) -> Inicial | B16: =IF('Itens Consolidados'!E19="","",'Itens Consolidados'!E19) | C16: =IF('Itens Consolidados'!C19="","",'Itens Consolidados'!C19) -> 4 - Centro de eventos | D16: =IF('Itens Consolidados'!F19="","",'Itens Consolidados'!F19) -> 00.000.001.002 | E16: =IF('Itens Consolidados'!G19="","",'Itens Consolidados'!G19) -> 80408 | F16: =IF('Itens Consolidados'!H19="","",'Itens Consolidados'!H19) -> Piso de concreto polido | G16: =IF('Itens Consolidados'!I19="","",'Itens Consolidados'!I19) -> m² | H16: ='Itens Consolidados'!J19 -> 8709.7 | I16: ='Itens Consolidados'!K19 -> 18 | J16: ='Itens Consolidados'!L19 -> 156774.6 | K16: ='Itens Consolidados'!M19 -> 24.3 | L16: ='Itens Consolidados'!N19 -> 211645.71 | M16: ='Itens Consolidados'!O19 -> 25.2 | N16: ='Itens Consolidados'!P19 -> 219484.44 | O16: ='Itens Consolidados'!Q19 -> 24.75 | P16: ='Itens Consolidados'!R19 -> 215565.08
A17: =IF('Itens Consolidados'!D20="","",'Itens Consolidados'!D20) -> Inicial | B17: =IF('Itens Consolidados'!E20="","",'Itens Consolidados'!E20) | C17: =IF('Itens Consolidados'!C20="","",'Itens Consolidados'!C20) -> 5 - Foyer e restaurante | D17: =IF('Itens Consolidados'!F20="","",'Itens Consolidados'!F20) -> 00.001.001.001 | E17: =IF('Itens Consolidados'!G20="","",'Itens Consolidados'!G20) -> 80321 | F17: =IF('Itens Consolidados'!H20="","",'Itens Consolidados'!H20) -> Piso de concreto desempenado | G17: =IF('Itens Consolidados'!I20="","",'Itens Consolidados'!I20) -> m² | H17: ='Itens Consolidados'!J20 -> 2661.5 | I17: ='Itens Consolidados'!K20 -> 15 | J17: ='Itens Consolidados'!L20 -> 39922.5 | K17: ='Itens Consolidados'!M20 -> 20.25 | L17: ='Itens Consolidados'!N20 -> 53895.375 | M17: ='Itens Consolidados'!O20 -> 21 | N17: ='Itens Consolidados'!P20 -> 55891.5 | O17: ='Itens Consolidados'!Q20 -> 20.625 | P17: ='Itens Consolidados'!R20 -> 54893.438
A18: =IF('Itens Consolidados'!D21="","",'Itens Consolidados'!D21) -> Inicial | B18: =IF('Itens Consolidados'!E21="","",'Itens Consolidados'!E21) | C18: =IF('Itens Consolidados'!C21="","",'Itens Consolidados'!C21) -> 5 - Foyer e restaurante | D18: =IF('Itens Consolidados'!F21="","",'Itens Consolidados'!F21) -> 00.002.001.001 | E18: =IF('Itens Consolidados'!G21="","",'Itens Consolidados'!G21) -> 80321 | F18: =IF('Itens Consolidados'!H21="","",'Itens Consolidados'!H21) -> Piso de concreto polido | G18: =IF('Itens Consolidados'!I21="","",'Itens Consolidados'!I21) -> m² | H18: ='Itens Consolidados'!J21 -> 709.5 | I18: ='Itens Consolidados'!K21 -> 18 | J18: ='Itens Consolidados'!L21 -> 12771 | K18: ='Itens Consolidados'!M21 -> 24.3 | L18: ='Itens Consolidados'!N21 -> 17240.85 | M18: ='Itens Consolidados'!O21 -> 25.2 | N18: ='Itens Consolidados'!P21 -> 17879.4 | O18: ='Itens Consolidados'!Q21 -> 24.75 | P18: ='Itens Consolidados'!R21 -> 17560.125
A19: Total dos itens iniciais | J19: =SUM(J15:J18) -> 241857.6 | L19: =SUM(L15:L18) -> 326507.76 | N19: =SUM(N15:N18) -> 338600.64 | P19: =SUM(P15:P18) -> 332554.2
A20: =IF('Itens Consolidados'!D22="","",'Itens Consolidados'!D22) -> Aditivo 1 | B20: =IF('Itens Consolidados'!E22="","",'Itens Consolidados'!E22) -> 24/07/2026 | C20: =IF('Itens Consolidados'!C22="","",'Itens Consolidados'!C22) -> 4 - Centro de eventos | D20: =IF('Itens Consolidados'!F22="","",'Itens Consolidados'!F22) -> 00.000.001.001 | E20: =IF('Itens Consolidados'!G22="","",'Itens Consolidados'!G22) -> 80407 | F20: =IF('Itens Consolidados'!H22="","",'Itens Consolidados'!H22) -> Piso de concreto desempenado | G20: =IF('Itens Consolidados'!I22="","",'Itens Consolidados'!I22) -> m² | H20: ='Itens Consolidados'!J22 -> 1982.43 | I20: ='Itens Consolidados'!K22 -> 15 | J20: ='Itens Consolidados'!L22 -> 29736.45 | K20: ='Itens Consolidados'!M22 -> 20.25 | L20: ='Itens Consolidados'!N22 -> 40144.207 | M20: ='Itens Consolidados'!O22 -> 21 | N20: ='Itens Consolidados'!P22 -> 41631.03 | O20: ='Itens Consolidados'!Q22 -> 20.625 | P20: ='Itens Consolidados'!R22 -> 40887.619
A21: =IF('Itens Consolidados'!D23="","",'Itens Consolidados'!D23) -> Aditivo 1 | B21: =IF('Itens Consolidados'!E23="","",'Itens Consolidados'!E23) -> 24/07/2026 | C21: =IF('Itens Consolidados'!C23="","",'Itens Consolidados'!C23) -> 4 - Centro de eventos | D21: =IF('Itens Consolidados'!F23="","",'Itens Consolidados'!F23) -> 00.000.001.002 | E21: =IF('Itens Consolidados'!G23="","",'Itens Consolidados'!G23) -> 80408 | F21: =IF('Itens Consolidados'!H23="","",'Itens Consolidados'!H23) -> Piso de concreto polido | G21: =IF('Itens Consolidados'!I23="","",'Itens Consolidados'!I23) -> m² | H21: ='Itens Consolidados'!J23 -> 1393.32 | I21: ='Itens Consolidados'!K23 -> 18 | J21: ='Itens Consolidados'!L23 -> 25079.76 | K21: ='Itens Consolidados'!M23 -> 24.3 | L21: ='Itens Consolidados'!N23 -> 33857.676 | M21: ='Itens Consolidados'!O23 -> 25.2 | N21: ='Itens Consolidados'!P23 -> 35111.664 | O21: ='Itens Consolidados'!Q23 -> 24.75 | P21: ='Itens Consolidados'!R23 -> 34484.67
A22: Total do aditivo 1 | J22: =SUM(J20:J21) -> 54816.21 | L22: =SUM(L20:L21) -> 74001.883 | N22: =SUM(N20:N21) -> 76742.694 | P22: =SUM(P20:P21) -> 75372.289
A23: TOTAL DO CONTRATO CT/164 | J23: =J19+J22 -> 296673.81 | L23: =L19+L22 -> 400509.64 | N23: =N19+N22 -> 415343.33 | P23: =P19+P22 -> 407926.49
A24: Acréscimo gerado pelo markup aplicado | P24: =P23-J23 -> 111252.68

Sheet CT-196
A1: CT/196 — ROSENILDE RODRIGUES LINDOLFO DE SOUZA
A2: Arquivo de origem: CT196__Fabio_Gesso__R00.pdf | Obra: 40200 - Empreita Recanto Cataratas Thermas Resort
A4: CNPJ do fornecedor | D4: 42.578.638/0001-54
A5: Data do contrato | D5: 27/05/2026
A6: Vigência | D6: 18/05/2026 a 20/06/2026
A7: Tipo de contrato | D7: 2 - Somente mão de obra sem retenção de INSS e ISSQN
A8: Objeto | D8: Fornecimento de mão de obra especializada para montagem e execução de paredes em drywall, conforme especificações do projeto.
A9: Impostos / retenção | D9: INSS SOBRE SALÁRIO 100% * 11% e ISSQN 100% * 5% sobre mão de obra
A11: ADITIVOS
A12: Aditivo 1 — 03/07/2026 | D12: Aditivo referente a mais 700 m² de parede dupla de drywall.
A13: Aditivo 2 — 31/07/2026 | D13: Execução de forro em gesso acartonado, execução de requadros em gesso acartonado e execução de paredes em Steelframe.
A15: Origem | B15: Data do aditivo | C15: Unid. construtiva | D15: Referência | E15: Código | F15: Descrição | G15: Un. | H15: Quantidade | I15: Vl. unit. original | J15: Total original | K15: Vl. unit. +35% | L15: Total +35% | M15: Vl. unit. +40% | N15: Total +40% | O15: Vl. unit. aplicado | P15: Total aplicado
A16: =IF('Itens Consolidados'!D24="","",'Itens Consolidados'!D24) -> Inicial | B16: =IF('Itens Consolidados'!E24="","",'Itens Consolidados'!E24) | C16: =IF('Itens Consolidados'!C24="","",'Itens Consolidados'!C24) -> 4 - Centro de eventos | D16: =IF('Itens Consolidados'!F24="","",'Itens Consolidados'!F24) -> 00.001.001.001 | E16: =IF('Itens Consolidados'!G24="","",'Itens Consolidados'!G24) -> 80388 | F16: =IF('Itens Consolidados'!H24="","",'Itens Consolidados'!H24) -> Execução de parede em drywall, composta por estrutura simples em perfis metálicos galvanizados, com fechamento em chapas ST, incluindo montagem, fixação e acabamentos necessários. | G16: =IF('Itens Consolidados'!I24="","",'Itens Consolidados'!I24) -> m² | H16: ='Itens Consolidados'!J24 -> 500 | I16: ='Itens Consolidados'!K24 -> 65 | J16: ='Itens Consolidados'!L24 -> 32500 | K16: ='Itens Consolidados'!M24 -> 87.75 | L16: ='Itens Consolidados'!N24 -> 43875 | M16: ='Itens Consolidados'!O24 -> 91 | N16: ='Itens Consolidados'!P24 -> 45500 | O16: ='Itens Consolidados'!Q24 -> 89.375 | P16: ='Itens Consolidados'!R24 -> 44687.5
A17: Total dos itens iniciais | J17: =SUM(J16:J16) -> 32500 | L17: =SUM(L16:L16) -> 43875 | N17: =SUM(N16:N16) -> 45500 | P17: =SUM(P16:P16) -> 44687.5
A18: =IF('Itens Consolidados'!D25="","",'Itens Consolidados'!D25) -> Aditivo 1 | B18: =IF('Itens Consolidados'!E25="","",'Itens Consolidados'!E25) -> 03/07/2026 | C18: =IF('Itens Consolidados'!C25="","",'Itens Consolidados'!C25) -> 4 - Centro de eventos | D18: =IF('Itens Consolidados'!F25="","",'Itens Consolidados'!F25) -> 00.001.001.001 | E18: =IF('Itens Consolidados'!G25="","",'Itens Consolidados'!G25) -> 80388 | F18: =IF('Itens Consolidados'!H25="","",'Itens Consolidados'!H25) -> Execução de parede em drywall, composta por estrutura simples em perfis metálicos galvanizados, com fechamento em chapas ST, incluindo montagem, fixação e acabamentos necessários. | G18: =IF('Itens Consolidados'!I25="","",'Itens Consolidados'!I25) -> m² | H18: ='Itens Consolidados'!J25 -> 700 | I18: ='Itens Consolidados'!K25 -> 65 | J18: ='Itens Consolidados'!L25 -> 45500 | K18: ='Itens Consolidados'!M25 -> 87.75 | L18: ='Itens Consolidados'!N25 -> 61425 | M18: ='Itens Consolidados'!O25 -> 91 | N18: ='Itens Consolidados'!P25 -> 63700 | O18: ='Itens Consolidados'!Q25 -> 89.375 | P18: ='Itens Consolidados'!R25 -> 62562.5
A19: Total do aditivo 1 | J19: =SUM(J18:J18) -> 45500 | L19: =SUM(L18:L18) -> 61425 | N19: =SUM(N18:N18) -> 63700 | P19: =SUM(P18:P18) -> 62562.5
A20: =IF('Itens Consolidados'!D26="","",'Itens Consolidados'!D26) -> Aditivo 2 | B20: =IF('Itens Consolidados'!E26="","",'Itens Consolidados'!E26) -> 31/07/2026 | C20: =IF('Itens Consolidados'!C26="","",'Itens Consolidados'!C26) -> 4 - Centro de eventos | D20: =IF('Itens Consolidados'!F26="","",'Itens Consolidados'!F26) -> 00.001.001.001 | E20: =IF('Itens Consolidados'!G26="","",'Itens Consolidados'!G26) -> 80388 | F20: =IF('Itens Consolidados'!H26="","",'Itens Consolidados'!H26) -> Execução de parede em drywall, composta por estrutura simples em perfis metálicos galvanizados, com fechamento em chapas ST, incluindo montagem, fixação e acabamentos necessários. | G20: =IF('Itens Consolidados'!I26="","",'Itens Consolidados'!I26) -> m² | H20: ='Itens Consolidados'!J26 -> 203.75 | I20: ='Itens Consolidados'!K26 -> 65 | J20: ='Itens Consolidados'!L26 -> 13243.75 | K20: ='Itens Consolidados'!M26 -> 87.75 | L20: ='Itens Consolidados'!N26 -> 17879.062 | M20: ='Itens Consolidados'!O26 -> 91 | N20: ='Itens Consolidados'!P26 -> 18541.25 | O20: ='Itens Consolidados'!Q26 -> 89.375 | P20: ='Itens Consolidados'!R26 -> 18210.156
A21: =IF('Itens Consolidados'!D27="","",'Itens Consolidados'!D27) -> Aditivo 2 | B21: =IF('Itens Consolidados'!E27="","",'Itens Consolidados'!E27) -> 31/07/2026 | C21: =IF('Itens Consolidados'!C27="","",'Itens Consolidados'!C27) -> 4 - Centro de eventos | D21: =IF('Itens Consolidados'!F27="","",'Itens Consolidados'!F27) -> 00.001.001.002 | E21: =IF('Itens Consolidados'!G27="","",'Itens Consolidados'!G27) -> 80362 | F21: =IF('Itens Consolidados'!H27="","",'Itens Consolidados'!H27) -> Execução de requadros em gesso acartonado. | G21: =IF('Itens Consolidados'!I27="","",'Itens Consolidados'!I27) -> m | H21: ='Itens Consolidados'!J27 -> 301.2 | I21: ='Itens Consolidados'!K27 -> 20 | J21: ='Itens Consolidados'!L27 -> 6024 | K21: ='Itens Consolidados'!M27 -> 27 | L21: ='Itens Consolidados'!N27 -> 8132.4 | M21: ='Itens Consolidados'!O27 -> 28 | N21: ='Itens Consolidados'!P27 -> 8433.6 | O21: ='Itens Consolidados'!Q27 -> 27.5 | P21: ='Itens Consolidados'!R27 -> 8283
A22: =IF('Itens Consolidados'!D28="","",'Itens Consolidados'!D28) -> Aditivo 2 | B22: =IF('Itens Consolidados'!E28="","",'Itens Consolidados'!E28) -> 31/07/2026 | C22: =IF('Itens Consolidados'!C28="","",'Itens Consolidados'!C28) -> 4 - Centro de eventos | D22: =IF('Itens Consolidados'!F28="","",'Itens Consolidados'!F28) -> 00.001.001.003 | E22: =IF('Itens Consolidados'!G28="","",'Itens Consolidados'!G28) -> 80388 | F22: =IF('Itens Consolidados'!H28="","",'Itens Consolidados'!H28) -> Execução de forro em gesso acartonado. | G22: =IF('Itens Consolidados'!I28="","",'Itens Consolidados'!I28) -> m² | H22: ='Itens Consolidados'!J28 -> 317.77 | I22: ='Itens Consolidados'!K28 -> 30 | J22: ='Itens Consolidados'!L28 -> 9533.1 | K22: ='Itens Consolidados'!M28 -> 40.5 | L22: ='Itens Consolidados'!N28 -> 12869.685 | M22: ='Itens Consolidados'!O28 -> 42 | N22: ='Itens Consolidados'!P28 -> 13346.34 | O22: ='Itens Consolidados'!Q28 -> 41.25 | P22: ='Itens Consolidados'!R28 -> 13108.013
A23: =IF('Itens Consolidados'!D29="","",'Itens Consolidados'!D29) -> Aditivo 2 | B23: =IF('Itens Consolidados'!E29="","",'Itens Consolidados'!E29) -> 31/07/2026 | C23: =IF('Itens Consolidados'!C29="","",'Itens Consolidados'!C29) -> 4 - Centro de eventos | D23: =IF('Itens Consolidados'!F29="","",'Itens Consolidados'!F29) -> 00.001.001.004 | E23: =IF('Itens Consolidados'!G29="","",'Itens Consolidados'!G29) -> 80388 | F23: =IF('Itens Consolidados'!H29="","",'Itens Consolidados'!H29) -> Execução de paredes em Steelframe com MDF. | G23: =IF('Itens Consolidados'!I29="","",'Itens Consolidados'!I29) -> m² | H23: ='Itens Consolidados'!J29 -> 253.46 | I23: ='Itens Consolidados'!K29 -> 70 | J23: ='Itens Consolidados'!L29 -> 17742.2 | K23: ='Itens Consolidados'!M29 -> 94.5 | L23: ='Itens Consolidados'!N29 -> 23951.97 | M23: ='Itens Consolidados'!O29 -> 98 | N23: ='Itens Consolidados'!P29 -> 24839.08 | O23: ='Itens Consolidados'!Q29 -> 96.25 | P23: ='Itens Consolidados'!R29 -> 24395.525
